Workbook

Sheet Instrucciones iniciales
B2: Pasos Iniciales:
B4: • Para pooder usar está calculadora, deberás hacer una copia de este archivo, para eso ve a la parte superior izquierda donde dice
B5: Archivo o Files, da click y se va a desplegar una pestaña, luego ve donde dice Crear una copia o Make a copy.
B14: • Luego te saldrá la ventana emergente que encuentras abajo para que le pongas el nombre que tu quieras y elijas en que lugar
B15: de tu Google Drive lo quieres guardar.
B37: • NOTA: Este archivo esta creado para usarse en Google Drive, puedes descargar su versión en Excel pero no se garantiza que las
B38: formúlas funcionen igual.

Sheet Hoja de Datos
B2: Cómo usar (Hoja de Datos)
B3: • Selecciona la MONEDA en la celda C7 en la que llevas tus finanzas.
B4: • Los datos de las columnas B, C, D y E los puedes modificar de acuerdo a tus necesidades, puedes dejar unicamente los nombres de los
B5: pilares, inversión, entidades y monedas que hagan parte de tu plan financiero.
B7: Selecciona tú moneda: | C7: COP
B9: Pilar | C9: Nombre Inversión | D9: Entidades o Empresas | E9: Monedas
B10: Fondo de Imprevistos | C10: Fondo de Imprevistos | D10: Skandia | E10: USD
B11: Reserva de Oxigeno | C11: Reserva de Oxigeno | D11: BBVA | E11: COP
B12: Cuenta de Retiro | C12: Arch Finance | D12: Bancolombia | E12: USD
B13: Cuenta de Inversiones | C13: Crea Patrimonio | D13: NU | E13: EUR
B14: Objetivo 1 (Reemplaza el nombre) | C14: Evo 10 | D14: ITA | E14: JPY
B15: Objetivo 2 (Reemplaza el nombre) | C15: Trinity 15 años | D15: Trinity | E15: GBP
B16: Objetivo 3 (Reemplaza el nombre) | C16: Global66 Dolares | D16: Interactive Brokers | E16: CHF
B17: Objetivo 4 (Reemplaza el nombre) | C17: Apto de la 97 Gallery | D17: Banco de Bogotá | E17: CAD
B18: Objetivo 5 (Reemplaza el nombre) | C18: VOO | D18: Davivienda | E18: AUD
B19: Objetivo 6 (Reemplaza el nombre) | C19: Inversión 2 | D19: BBVA Colombia | E19: NZD
B20: Objetivo 7 (Reemplaza el nombre) | C20: Inversión 3 | D20: Scotiabank Colpatria | E20: CNY
C21: Inversión... | D21: Banco de Occidente | E21: HKD
D22: Banco Agrario | E22: SGD
D23: Banco Popular | E23: KRW
D24: Banco AV Villas | E24: SEK
D25: Banco Caja Social | E25: NOK
D26: Itaú Colombia | E26: DKK
D27: Banco GNB Sudameris | E27: MXN
D28: Banco Falabella | E28: CLP
D29: Banco Finandina | E29: ARS
D30: Citibank Colombia | E30: PEN
D31: Banco W | E31: COP
D32: Coopcentral | E32: BRL
D33: Fiduciaria Bancolombia | E33: UYU
... D50: Fiduoccidente | E50: ILS
D51: Fiducoomeva
D52: Protección
D53: Porvenir
D54: Colfondos
D55: Skandia
D56: Acciones & Valores
D57: Alianza Valores
D58: Valores Bancolombia
D59: Davivienda Corredores
...

Sheet Entradas y salidas
B2: Cómo usar (Entradas y salidas)
B3: • Modifica unicamente las celdas que están en color amarillo.
B4: • No toques las celdas en color verde.
B5: • Si tú inversión es en dólares debes poner el valor que invertiste en tu moneda local en la columna G y el valor
B6: de la TRM en la columna H. Es decir, a que precio estaba el dólar el día que hiciste la inversión.
B8: Pilar | C8: Entidad o Empresa | D8: Inversión | E8: Moneda (USD/COP) | F8: Fecha | G8: Aporte en COP (+) o tú moneda | H8: TRM (COP/USD) o (Tú moneda/USD) | I8: Flujo USD (auto) | J8: Flujo COP (auto) o tú moneda | K8: Flujo COP (auto) o tú moneda en USD | L8: Nota
B9: Fondo de Imprevistos | C9: NU | D9: Fondo de Imprevistos | E9: COP | F9: 45306 | G9: 5000000 | I9: =IFERROR(IF(E9="USD",-(G9/H9),""),"") | J9: =IF(E9='Hoja de Datos'!$C$7,-(G9),"") -> -5000000 | K9: =IF(E9='Hoja de Datos'!$C$7,"", IF(G9="","", -G9)) | L9: aporte 1
B10: Reserva de Oxigeno | C10: Skandia | D10: Reserva de Oxigeno | E10: COP | F10: 45361 | G10: 3000000 | I10: =IFERROR(IF(E10="USD",-(G10/H10),""),"") | J10: =IF(E10='Hoja de Datos'!$C$7,-(G10),"") -> -3000000 | K10: =IF(E10='Hoja de Datos'!$C$7,"", IF(G10="","", -G10)) | L10: aporte 2
B11: Fondo de Imprevistos | C11: Skandia | D11: Reserva de Oxigeno | E11: COP | F11: 45323 | G11: 3000000 | I11: =IFERROR(IF(E11="USD",-(G11/H11),""),"") | J11: =IF(E11='Hoja de Datos'!$C$7,-(G11),"") -> -3000000 | K11: =IF(E11='Hoja de Datos'!$C$7,"", IF(G11="","", -G11)) | L11: aporte 1
B12: Fondo de Imprevistos | C12: Skandia | D12: Reserva de Oxigeno | E12: COP | F12: 45397 | G12: 3000000 | I12: =IFERROR(IF(E12="USD",-(G12/H12),""),"") | J12: =IF(E12='Hoja de Datos'!$C$7,-(G12),"") -> -3000000 | K12: =IF(E12='Hoja de Datos'!$C$7,"", IF(G12="","", -G12)) | L12: aporte 2
B13: Fondo de Imprevistos | C13: Skandia | D13: Reserva de Oxigeno | E13: COP | F13: 45311 | G13: 2000000 | I13: =IFERROR(IF(E13="USD",-(G13/H13),""),"") | J13: =IF(E13='Hoja de Datos'!$C$7,-(G13),"") -> -2000000 | K13: =IF(E13='Hoja de Datos'!$C$7,"", IF(G13="","", -G13)) | L13: aporte 1
B14: Fondo de Imprevistos | C14: Skandia | D14: Reserva de Oxigeno | E14: COP | F14: 45432 | G14: 2000000 | I14: =IFERROR(IF(E14="USD",-(G14/H14),""),"") | J14: =IF(E14='Hoja de Datos'!$C$7,-(G14),"") -> -2000000 | K14: =IF(E14='Hoja de Datos'!$C$7,"", IF(G14="","", -G14)) | L14: aporte 2
B15: Fondo de Imprevistos | C15: Skandia | D15: Reserva de Oxigeno | E15: COP | F15: 45356 | G15: 500000 | I15: =IFERROR(IF(E15="USD",-(G15/H15),""),"") | J15: =IF(E15='Hoja de Datos'!$C$7,-(G15),"") -> -500000 | K15: =IF(E15='Hoja de Datos'!$C$7,"", IF(G15="","", -G15)) | L15: aporte 1
B16: Fondo de Imprevistos | C16: Skandia | D16: Reserva de Oxigeno | E16: COP | F16: 45448 | G16: 500000 | I16: =IFERROR(IF(E16="USD",-(G16/H16),""),"") | J16: =IF(E16='Hoja de Datos'!$C$7,-(G16),"") -> -500000 | K16: =IF(E16='Hoja de Datos'!$C$7,"", IF(G16="","", -G16)) | L16: aporte 2
B17: Fondo de Imprevistos | C17: NU | D17: Fondo de Imprevistos | E17: COP | F17: 45332 | G17: 1000000 | I17: =IFERROR(IF(E17="USD",-(G17/H17),""),"") | J17: =IF(E17='Hoja de Datos'!$C$7,-(G17),"") -> -1000000 | K17: =IF(E17='Hoja de Datos'!$C$7,"", IF(G17="","", -G17)) | L17: aporte COP
B18: Fondo de Imprevistos | C18: NU | D18: Fondo de Imprevistos | E18: COP | F18: 45361 | G18: 300000 | I18: =IFERROR(IF(E18="USD",-(G18/H18),""),"") | J18: =IF(E18='Hoja de Datos'!$C$7,-(G18),"") -> -300000 | K18: =IF(E18='Hoja de Datos'!$C$7,"", IF(G18="","", -G18)) | L18: aporte USD
B19: Cuenta de Inversiones | C19: ITA | D19: Evo 10 | E19: USD | F19: 44848 | G19: 11050000 | H19: 4420 | I19: =IFERROR(IF(E19="USD",-(G19/H19),""),"") -> -2500 | J19: =IF(E19='Hoja de Datos'!$C$7,-(G19),"") | K19: =IF(E19='Hoja de Datos'!$C$7,"", IF(G19="","", -G19)) -> -11050000
B20: Cuenta de Inversiones | C20: ITA | D20: Evo 10 | E20: USD | F20: 45211 | G20: 10897500 | H20: 4359 | I20: =IFERROR(IF(E20="USD",-(G20/H20),""),"") -> -2500 | J20: =IF(E20='Hoja de Datos'!$C$7,-(G20),"") | K20: =IF(E20='Hoja de Datos'!$C$7,"", IF(G20="","", -G20)) -> -10897500
B21: Cuenta de Inversiones | C21: ITA | D21: Evo 10 | E21: USD | F21: 45583 | G21: 10665000 | H21: 4266 | I21: =IFERROR(IF(E21="USD",-(G21/H21),""),"") -> -2500 | J21: =IF(E21='Hoja de Datos'!$C$7,-(G21),"") | K21: =IF(E21='Hoja de Datos'!$C$7,"", IF(G21="","", -G21)) -> -10665000
B22: Cuenta de Inversiones | C22: ITA | D22: Evo 10 | E22: USD | F22: 45944 | G22: 9737500 | H22: 3895 | I22: =IFERROR(IF(E22="USD",-(G22/H22),""),"") -> -2500 | J22: =IF(E22='Hoja de Datos'!$C$7,-(G22),"") | K22: =IF(E22='Hoja de Datos'!$C$7,"", IF(G22="","", -G22)) -> -9737500
B23: Cuenta de Inversiones | C23: Trinity | D23: Trinity 15 años | E23: USD | F23: 44848 | G23: 13260000 | H23: 4420 | I23: =IFERROR(IF(E23="USD",-(G23/H23),""),"") -> -3000 | J23: =IF(E23='Hoja de Datos'!$C$7,-(G23),"") | K23: =IF(E23='Hoja de Datos'!$C$7,"", IF(G23="","", -G23)) -> -13260000
B24: Cuenta de Inversiones | C24: Trinity | D24: Trinity 15 años | E24: USD | F24: 45211 | G24: 13077000 | H24: 4359 | I24: =IFERROR(IF(E24="USD",-(G24/H24),""),"") -> -3000 | J24: =IF(E24='Hoja de Datos'!$C$7,-(G24),"") | K24: =IF(E24='Hoja de Datos'!$C$7,"", IF(G24="","", -G24)) -> -13077000
B25: Cuenta de Inversiones | C25: Interactive Brokers | D25: VOO | E25: USD | F25: 45611 | G25: 8950000 | H25: 4475 | I25: =IFERROR(IF(E25="USD",-(G25/H25),""),"") -> -2000 | J25: =IF(E25='Hoja de Datos'!$C$7,-(G25),"") | K25: =IF(E25='Hoja de Datos'!$C$7,"", IF(G25="","", -G25)) -> -8950000
I26: =IFERROR(IF(E26="USD",-(G26/H26),""),"") | J26: =IF(E26='Hoja de Datos'!$C$7,-(G26),"") | K26: =IF(E26='Hoja de Datos'!$C$7,"", IF(G26="","", -G26))
I27: =IFERROR(IF(E27="USD",-(G27/H27),""),"") | J27: =IF(E27='Hoja de Datos'!$C$7,-(G27),"") | K27: =IF(E27='Hoja de Datos'!$C$7,"", IF(G27="","", -G27))
I28: =IFERROR(IF(E28="USD",-(G28/H28),""),"") | J28: =IF(E28='Hoja de Datos'!$C$7,-(G28),"") | K28: =IF(E28='Hoja de Datos'!$C$7,"", IF(G28="","", -G28))
I29: =IFERROR(IF(E29="USD",-(G29/H29),""),"") | J29: =IF(E29='Hoja de Datos'!$C$7,-(G29),"") | K29: =IF(E29='Hoja de Datos'!$C$7,"", IF(G29="","", -G29))
I30: =IFERROR(IF(E30="USD",-(G30/H30),""),"") | J30: =IF(E30='Hoja de Datos'!$C$7,-(G30),"") | K30: =IF(E30='Hoja de Datos'!$C$7,"", IF(G30="","", -G30))
I31: =IFERROR(IF(E31="USD",-(G31/H31),""),"") | J31: =IF(E31='Hoja de Datos'!$C$7,-(G31),"") | K31: =IF(E31='Hoja de Datos'!$C$7,"", IF(G31="","", -G31))
I32: =IFERROR(IF(E32="USD",-(G32/H32),""),"") | J32: =IF(E32='Hoja de Datos'!$C$7,-(G32),"") | K32: =IF(E32='Hoja de Datos'!$C$7,"", IF(G32="","", -G32))
I33: =IFERROR(IF(E33="USD",-(G33/H33),""),"") | J33: =IF(E33='Hoja de Datos'!$C$7,-(G33),"") | K33: =IF(E33='Hoja de Datos'!$C$7,"", IF(G33="","", -G33))
I34: =IFERROR(IF(E34="USD",-(G34/H34),""),"") | J34: =IF(E34='Hoja de Datos'!$C$7,-(G34),"") | K34: =IF(E34='Hoja de Datos'!$C$7,"", IF(G34="","", -G34))
I35: =IFERROR(IF(E35="USD",-(G35/H35),""),"") | J35: =IF(E35='Hoja de Datos'!$C$7,-(G35),"") | K35: =IF(E35='Hoja de Datos'!$C$7,"", IF(G35="","", -G35))
I36: =IFERROR(IF(E36="USD",-(G36/H36),""),"") | J36: =IF(E36='Hoja de Datos'!$C$7,-(G36),"") | K36: =IF(E36='Hoja de Datos'!$C$7,"", IF(G36="","", -G36))
I37: =IFERROR(IF(E37="USD",-(G37/H37),""),"") | J37: =IF(E37='Hoja de Datos'!$C$7,-(G37),"") | K37: =IF(E37='Hoja de Datos'!$C$7,"", IF(G37="","", -G37))
... I1993: =IFERROR(IF(E1993="USD",-(G1993/H1993),""),"") | J1993: =IF(E1993='Hoja de Datos'!$C$7,-(G1993),"") | K1993: =IF(E1993='Hoja de Datos'!$C$7,"", IF(G1993="","", -G1993))

Sheet Cortes x inversión
B2: Cómo usar (Cortes x inversión) | G2: Valor Dólar Hoy: | H2: =IFERROR(__xludf.DUMMYFUNCTION("GOOGLEFINANCE(""CURRENCY:USDCOP"")"),3768.28) -> 3768.28
B3: • Modifica unicamente las celdas que están en color amarillo.
B4: • No toques las celdas en color verde.
B5: • Cuando la inversión es en tú moneda local pon el valor en la columna F, cuando es en dólares
B6: pon el valor actual en dólares columna H y el valor de la TRM del día que estás revisando tu inversión.
B8: Pilar | C8: Entidad o Empresa | D8: Inversión | E8: Moneda (USD/COP) | F8: Valor final COP (+) o tú moneda | G8: Valor final USD (+) | H8: TRM final (COP/USD) o (Tú moneda/USD) | I8: Valor final USD a COP o tú moneda | J8: Fecha de corte | K8: Nota
B9: Fondo de Imprevistos | C9: NU | D9: Fondo de Imprevistos | E9: COP | F9: 6500000 | I9: =IF(G9>0, G9*H9, ) | J9: 45971
B10: Reserva de Oxigeno | C10: Skandia | D10: Reserva de Oxigeno | E10: COP | F10: 15000000 | I10: =IF(G10>0, G10*H10, ) | J10: 45971
B11: Cuenta de Retiro | C11: Trinity | D11: Trinity 15 años | E11: USD | G11: 6300 | H11: 3770 | I11: =IF(G11>0, G11*H11, ) -> 23751000 | J11: 45971
B12: Cuenta de Inversiones | C12: ITA | D12: Evo 10 | E12: USD | G12: 12000 | H12: 3770 | I12: =IF(G12>0, G12*H12, ) -> 45240000 | J12: 45971
B13: Cuenta de Inversiones | C13: Interactive Brokers | D13: VOO | E13: USD | G13: 2400 | H13: 3770 | I13: =IF(G13>0, G13*H13, ) -> 9048000 | J13: 45971
I14: =IF(G14>0, G14*H14, )
I15: =IF(G15>0, G15*H15, )
I16: =IF(G16>0, G16*H16, )
I17: =IF(G17>0, G17*H17, )
I18: =IF(G18>0, G18*H18, )
I19: =IF(G19>0, G19*H19, )
I20: =IF(G20>0, G20*H20, )
I21: =IF(G21>0, G21*H21, )
I22: =IF(G22>0, G22*H22, )
I23: =IF(G23>0, G23*H23, )
I24: =IF(G24>0, G24*H24, )
I25: =IF(G25>0, G25*H25, )
... I1001: =IF(G1001>0, G1001*H1001, )

Sheet Resultados x inversión
B2: Cómo usar (Resultados x inversión)
B3: • Modifica unicamente las celdas que están en color amarillo. Debes elegir los datos de las inversiones que quieres ver.
B4: • No toques las celdas en color verde.
B5: • Acá los datos que te interesará revisar son los que se encuentran en la columna I, N y T
B6: ahí verás el retorno sobre la inversión en tu moneda, en dólares y en dólares convertirdo a tu moneda local.
B8: Pilar | C8: Entidad o Empresa | D8: Inversión | E8: Moneda (USD/COP) | F8: Total aportado COP o tú moneda | G8: Valor final COP o tú moneda | H8: Ganancia/Pérdida COP | I8: TIR COP | K8: Total aportado USD | L8: Valor final USD | M8: Ganancia/Pérdida USD | N8: TIR USD | P8: Valor USD | Q8: Total aportado USD a COP o tú moneda | R8: Valor final USD a COP o tú moneda | S8: Ganancia/Pérdida USD a COP o tú moneda | T8: TIR USD a COP o tú moneda
B9: Fondo de Imprevistos | C9: NU | D9: Fondo de Imprevistos | E9: COP | F9: =IF(E9="COP", SUMIF('Entradas y salidas'!D:D, D9, 'Entradas y salidas'!J:J), ) -> -6300000 | G9: =IFERROR(__xludf.DUMMYFUNCTION("IF(E9=""COP"", INDEX(FILTER('Cortes x inversión'!F:F, 'Cortes x inversión'!D:D=D9),1), )"),6500000.0) -> 6500000 | H9: =IF(OR(F9="", G9=""),"", G9 - ABS(F9)) -> 200000 | I9: =IFERROR(__xludf.DUMMYFUNCTION("IF(ISBLANK(D9),"""",IFERROR(XIRR({FILTER('Entradas y salidas'!J:J, 'Entradas y salidas'!D:D=D9, NOT(ISBLANK('Entradas y salidas'!J:J))); INDEX(FILTER('Cortes x inversión'!F:F, 'Cortes x inversión'!D:D=D9),1)}, {FILTER('Entradas y salidas'!F:F, 'Entradas y"&" salidas'!D:D=D9, NOT(ISBLANK('Entradas y salidas'!J:J))); INDEX(FILTER('Cortes x inversión'!J:J, 'Cortes x inversión'!D:D=D9),1)}), """"))"),0.017480343914977887) -> 0.017480344 | K9: =IF(E9="USD", SUMIF('Entradas y salidas'!D:D, D9, 'Entradas y salidas'!I:I), ) | L9: =IFERROR(__xludf.DUMMYFUNCTION("IF(E9=""USD"", INDEX(FILTER('Cortes x inversión'!G:G, 'Cortes x inversión'!D:D=D9),1), )"),"") | M9: =IF(OR(K9="", L9=""),"", L9 - ABS(K9)) | N9: =IFERROR(__xludf.DUMMYFUNCTION("IF(ISBLANK(D9),"""",IFERROR(XIRR({FILTER('Entradas y salidas'!I:I, 'Entradas y salidas'!D:D=D9, NOT(ISBLANK('Entradas y salidas'!I:I))); INDEX(FILTER('Cortes x inversión'!G:G, 'Cortes x inversión'!D:D=D9),1)}, {FILTER('Entradas y salidas'!F:F, 'Entradas y"&" salidas'!D:D=D9, NOT(ISBLANK('Entradas y salidas'!I:I))); INDEX(FILTER('Cortes x inversión'!J:J, 'Cortes x inversión'!D:D=D9),1)}), """"))"),"") | P9: =IFERROR(__xludf.DUMMYFUNCTION("IF(K9="""","""", GOOGLEFINANCE(""CURRENCY:USDCOP"")) "),"") | Q9: =IF(K9="","", K9*P9) | R9: =IF(K9="","", L9*P9) | S9: =IF(OR(Q9="", R9=""),"", R9 - ABS(Q9)) | T9: =IFERROR(__xludf.DUMMYFUNCTION("IF(ISBLANK(D9),"""",IFERROR(XIRR({FILTER('Entradas y salidas'!K:K, 'Entradas y salidas'!D:D=D9, NOT(ISBLANK('Entradas y salidas'!K:K))); INDEX(FILTER('Cortes x inversión'!I:I, 'Cortes x inversión'!D:D=D9),1)}, {FILTER('Entradas y salidas'!F:F, 'Entradas y"&" salidas'!D:D=D9, NOT(ISBLANK('Entradas y salidas'!K:K))); INDEX(FILTER('Cortes x inversión'!J:J, 'Cortes x inversión'!D:D=D9),1)}), """"))"),"")
B10: Reserva de Oxigeno | C10: Skandia | D10: Reserva de Oxigeno | E10: COP | F10: =IF(E10="COP", SUMIF('Entradas y salidas'!D:D, D10, 'Entradas y salidas'!J:J), ) -> -14000000 | G10: =IFERROR(__xludf.DUMMYFUNCTION("IF(E10=""COP"", INDEX(FILTER('Cortes x inversión'!F:F, 'Cortes x inversión'!D:D=D10),1), )"),1.5E7) -> 15000000 | H10: =IF(OR(F10="", G10=""),"", G10 - ABS(F10)) -> 1000000 | I10: =IFERROR(__xludf.DUMMYFUNCTION("IF(ISBLANK(D10),"""",IFERROR(XIRR({FILTER('Entradas y salidas'!J:J, 'Entradas y salidas'!D:D=D10, NOT(ISBLANK('Entradas y salidas'!J:J))); INDEX(FILTER('Cortes x inversión'!F:F, 'Cortes x inversión'!D:D=D10),1)}, {FILTER('Entradas y salidas'!F:F, 'Entrada"&"s y salidas'!D:D=D10, NOT(ISBLANK('Entradas y salidas'!J:J))); INDEX(FILTER('Cortes x inversión'!J:J, 'Cortes x inversión'!D:D=D10),1)}), """"))"),0.04253030082479297) -> 0.042530301 | K10: =IF(E10="USD", SUMIF('Entradas y salidas'!D:D, D10, 'Entradas y salidas'!I:I), ) | L10: =IFERROR(__xludf.DUMMYFUNCTION("IF(E10=""USD"", INDEX(FILTER('Cortes x inversión'!G:G, 'Cortes x inversión'!D:D=D10),1), )"),"") | M10: =IF(OR(K10="", L10=""),"", L10 - ABS(K10)) | N10: =IFERROR(__xludf.DUMMYFUNCTION("IF(ISBLANK(D10),"""",IFERROR(XIRR({FILTER('Entradas y salidas'!I:I, 'Entradas y salidas'!D:D=D10, NOT(ISBLANK('Entradas y salidas'!I:I))); INDEX(FILTER('Cortes x inversión'!G:G, 'Cortes x inversión'!D:D=D10),1)}, {FILTER('Entradas y salidas'!F:F, 'Entrada"&"s y salidas'!D:D=D10, NOT(ISBLANK('Entradas y salidas'!I:I))); INDEX(FILTER('Cortes x inversión'!J:J, 'Cortes x inversión'!D:D=D10),1)}), """"))"),"") | P10: =IFERROR(__xludf.DUMMYFUNCTION("IF(K10="""","""", GOOGLEFINANCE(""CURRENCY:USDCOP"")) "),"") | Q10: =IF(K10="","", K10*P10) | R10: =IF(K10="","", L10*P10) | S10: =IF(OR(Q10="", R10=""),"", R10 - ABS(Q10)) | T10: =IFERROR(__xludf.DUMMYFUNCTION("IF(ISBLANK(D10),"""",IFERROR(XIRR({FILTER('Entradas y salidas'!K:K, 'Entradas y salidas'!D:D=D10, NOT(ISBLANK('Entradas y salidas'!K:K))); INDEX(FILTER('Cortes x inversión'!I:I, 'Cortes x inversión'!D:D=D10),1)}, {FILTER('Entradas y salidas'!F:F, 'Entrada"&"s y salidas'!D:D=D10, NOT(ISBLANK('Entradas y salidas'!K:K))); INDEX(FILTER('Cortes x inversión'!J:J, 'Cortes x inversión'!D:D=D10),1)}), """"))"),"")
B11: Cuenta de Retiro | C11: Trinity | D11: Trinity 15 años | E11: USD | F11: =IF(E11="COP", SUMIF('Entradas y salidas'!D:D, D11, 'Entradas y salidas'!J:J), ) | G11: =IFERROR(__xludf.DUMMYFUNCTION("IF(E11=""COP"", INDEX(FILTER('Cortes x inversión'!F:F, 'Cortes x inversión'!D:D=D11),1), )"),"") | H11: =IF(OR(F11="", G11=""),"", G11 - ABS(F11)) | I11: =IFERROR(__xludf.DUMMYFUNCTION("IF(ISBLANK(D11),"""",IFERROR(XIRR({FILTER('Entradas y salidas'!J:J, 'Entradas y salidas'!D:D=D11, NOT(ISBLANK('Entradas y salidas'!J:J))); INDEX(FILTER('Cortes x inversión'!F:F, 'Cortes x inversión'!D:D=D11),1)}, {FILTER('Entradas y salidas'!F:F, 'Entrada"&"s y salidas'!D:D=D11, NOT(ISBLANK('Entradas y salidas'!J:J))); INDEX(FILTER('Cortes x inversión'!J:J, 'Cortes x inversión'!D:D=D11),1)}), """"))"),"") | K11: =IF(E11="USD", SUMIF('Entradas y salidas'!D:D, D11, 'Entradas y salidas'!I:I), ) -> -6000 | L11: =IFERROR(__xludf.DUMMYFUNCTION("IF(E11=""USD"", INDEX(FILTER('Cortes x inversión'!G:G, 'Cortes x inversión'!D:D=D11),1), )"),6300.0) -> 6300 | M11: =IF(OR(K11="", L11=""),"", L11 - ABS(K11)) -> 300 | N11: =IFERROR(__xludf.DUMMYFUNCTION("IF(ISBLANK(D11),"""",IFERROR(XIRR({FILTER('Entradas y salidas'!I:I, 'Entradas y salidas'!D:D=D11, NOT(ISBLANK('Entradas y salidas'!I:I))); INDEX(FILTER('Cortes x inversión'!G:G, 'Cortes x inversión'!D:D=D11),1)}, {FILTER('Entradas y salidas'!F:F, 'Entrada"&"s y salidas'!D:D=D11, NOT(ISBLANK('Entradas y salidas'!I:I))); INDEX(FILTER('Cortes x inversión'!J:J, 'Cortes x inversión'!D:D=D11),1)}), """"))"),0.019077510452035686) -> 0.01907751 | P11: =IFERROR(__xludf.DUMMYFUNCTION("IF(K11="""","""", GOOGLEFINANCE(""CURRENCY:USDCOP"")) "),3768.28) -> 3768.28 | Q11: =IF(K11="","", K11*P11) -> -22609680 | R11: =IF(K11="","", L11*P11) -> 23740164 | S11: =IF(OR(Q11="", R11=""),"", R11 - ABS(Q11)) -> 1130484 | T11: =IFERROR(__xludf.DUMMYFUNCTION("IF(ISBLANK(D11),"""",IFERROR(XIRR({FILTER('Entradas y salidas'!K:K, 'Entradas y salidas'!D:D=D11, NOT(ISBLANK('Entradas y salidas'!K:K))); INDEX(FILTER('Cortes x inversión'!I:I, 'Cortes x inversión'!D:D=D11),1)}, {FILTER('Entradas y salidas'!F:F, 'Entrada"&"s y salidas'!D:D=D11, NOT(ISBLANK('Entradas y salidas'!K:K))); INDEX(FILTER('Cortes x inversión'!J:J, 'Cortes x inversión'!D:D=D11),1)}), """"))"),-0.039297069217602426) -> -0.039297069
B12: Cuenta de Inversiones | C12: ITA | D12: Evo 10 | E12: USD | F12: =IF(E12="COP", SUMIF('Entradas y salidas'!D:D, D12, 'Entradas y salidas'!J:J), ) | G12: =IFERROR(__xludf.DUMMYFUNCTION("IF(E12=""COP"", INDEX(FILTER('Cortes x inversión'!F:F, 'Cortes x inversión'!D:D=D12),1), )"),"") | H12: =IF(OR(F12="", G12=""),"", G12 - ABS(F12)) | I12: =IFERROR(__xludf.DUMMYFUNCTION("IF(ISBLANK(D12),"""",IFERROR(XIRR({FILTER('Entradas y salidas'!J:J, 'Entradas y salidas'!D:D=D12, NOT(ISBLANK('Entradas y salidas'!J:J))); INDEX(FILTER('Cortes x inversión'!F:F, 'Cortes x inversión'!D:D=D12),1)}, {FILTER('Entradas y salidas'!F:F, 'Entrada"&"s y salidas'!D:D=D12, NOT(ISBLANK('Entradas y salidas'!J:J))); INDEX(FILTER('Cortes x inversión'!J:J, 'Cortes x inversión'!D:D=D12),1)}), """"))"),"") | K12: =IF(E12="USD", SUMIF('Entradas y salidas'!D:D, D12, 'Entradas y salidas'!I:I), ) -> -10000 | L12: =IFERROR(__xludf.DUMMYFUNCTION("IF(E12=""USD"", INDEX(FILTER('Cortes x inversión'!G:G, 'Cortes x inversión'!D:D=D12),1), )"),12000.0) -> 12000 | M12: =IF(OR(K12="", L12=""),"", L12 - ABS(K12)) -> 2000 | N12: =IFERROR(__xludf.DUMMYFUNCTION("IF(ISBLANK(D12),"""",IFERROR(XIRR({FILTER('Entradas y salidas'!I:I, 'Entradas y salidas'!D:D=D12, NOT(ISBLANK('Entradas y salidas'!I:I))); INDEX(FILTER('Cortes x inversión'!G:G, 'Cortes x inversión'!D:D=D12),1)}, {FILTER('Entradas y salidas'!F:F, 'Entrada"&"s y salidas'!D:D=D12, NOT(ISBLANK('Entradas y salidas'!I:I))); INDEX(FILTER('Cortes x inversión'!J:J, 'Cortes x inversión'!D:D=D12),1)}), """"))"),0.11731676240573267) -> 0.11731676 | P12: =IFERROR(__xludf.DUMMYFUNCTION("IF(K12="""","""", GOOGLEFINANCE(""CURRENCY:USDCOP"")) "),3768.28) -> 3768.28 | Q12: =IF(K12="","", K12*P12) -> -37682800 | R12: =IF(K12="","", L12*P12) -> 45219360 | S12: =IF(OR(Q12="", R12=""),"", R12 - ABS(Q12)) -> 7536560 | T12: =IFERROR(__xludf.DUMMYFUNCTION("IF(ISBLANK(D12),"""",IFERROR(XIRR({FILTER('Entradas y salidas'!K:K, 'Entradas y salidas'!D:D=D12, NOT(ISBLANK('Entradas y salidas'!K:K))); INDEX(FILTER('Cortes x inversión'!I:I, 'Cortes x inversión'!D:D=D12),1)}, {FILTER('Entradas y salidas'!F:F, 'Entrada"&"s y salidas'!D:D=D12, NOT(ISBLANK('Entradas y salidas'!K:K))); INDEX(FILTER('Cortes x inversión'!J:J, 'Cortes x inversión'!D:D=D12),1)}), """"))"),0.04086936142249945) -> 0.040869361
B13: Cuenta de Inversiones | C13: Interactive Brokers | D13: VOO | E13: USD | F13: =IF(E13="COP", SUMIF('Entradas y salidas'!D:D, D13, 'Entradas y salidas'!J:J), ) | G13: =IFERROR(__xludf.DUMMYFUNCTION("IF(E13=""COP"", INDEX(FILTER('Cortes x inversión'!F:F, 'Cortes x inversión'!D:D=D13),1), )"),"") | H13: =IF(OR(F13="", G13=""),"", G13 - ABS(F13)) | I13: =IFERROR(__xludf.DUMMYFUNCTION("IF(ISBLANK(D13),"""",IFERROR(XIRR({FILTER('Entradas y salidas'!J:J, 'Entradas y salidas'!D:D=D13, NOT(ISBLANK('Entradas y salidas'!J:J))); INDEX(FILTER('Cortes x inversión'!F:F, 'Cortes x inversión'!D:D=D13),1)}, {FILTER('Entradas y salidas'!F:F, 'Entrada"&"s y salidas'!D:D=D13, NOT(ISBLANK('Entradas y salidas'!J:J))); INDEX(FILTER('Cortes x inversión'!J:J, 'Cortes x inversión'!D:D=D13),1)}), """"))"),"") | K13: =IF(E13="USD", SUMIF('Entradas y salidas'!D:D, D13, 'Entradas y salidas'!I:I), ) -> -2000 | L13: =IFERROR(__xludf.DUMMYFUNCTION("IF(E13=""USD"", INDEX(FILTER('Cortes x inversión'!G:G, 'Cortes x inversión'!D:D=D13),1), )"),2400.0) -> 2400 | M13: =IF(OR(K13="", L13=""),"", L13 - ABS(K13)) -> 400 | N13: =IFERROR(__xludf.DUMMYFUNCTION("IF(ISBLANK(D13),"""",IFERROR(XIRR({FILTER('Entradas y salidas'!I:I, 'Entradas y salidas'!D:D=D13, NOT(ISBLANK('Entradas y salidas'!I:I))); INDEX(FILTER('Cortes x inversión'!G:G, 'Cortes x inversión'!D:D=D13),1)}, {FILTER('Entradas y salidas'!F:F, 'Entrada"&"s y salidas'!D:D=D13, NOT(ISBLANK('Entradas y salidas'!I:I))); INDEX(FILTER('Cortes x inversión'!J:J, 'Cortes x inversión'!D:D=D13),1)}), """"))"),0.20304254321810247) -> 0.20304254 | P13: =IFERROR(__xludf.DUMMYFUNCTION("IF(K13="""","""", GOOGLEFINANCE(""CURRENCY:USDCOP"")) "),3768.28) -> 3768.28 | Q13: =IF(K13="","", K13*P13) -> -7536560 | R13: =IF(K13="","", L13*P13) -> 9043872 | S13: =IF(OR(Q13="", R13=""),"", R13 - ABS(Q13)) -> 1507312 | T13: =IFERROR(__xludf.DUMMYFUNCTION("IF(ISBLANK(D13),"""",IFERROR(XIRR({FILTER('Entradas y salidas'!K:K, 'Entradas y salidas'!D:D=D13, NOT(ISBLANK('Entradas y salidas'!K:K))); INDEX(FILTER('Cortes x inversión'!I:I, 'Cortes x inversión'!D:D=D13),1)}, {FILTER('Entradas y salidas'!F:F, 'Entrada"&"s y salidas'!D:D=D13, NOT(ISBLANK('Entradas y salidas'!K:K))); INDEX(FILTER('Cortes x inversión'!J:J, 'Cortes x inversión'!D:D=D13),1)}), """"))"),0.011102641280031241) -> 0.011102641
F14: =IF(E14="COP", SUMIF('Entradas y salidas'!D:D, D14, 'Entradas y salidas'!J:J), ) | G14: =IFERROR(__xludf.DUMMYFUNCTION("IF(E14=""COP"", INDEX(FILTER('Cortes x inversión'!F:F, 'Cortes x inversión'!D:D=D14),1), )"),"") | H14: =IF(OR(F14="", G14=""),"", G14 - ABS(F14)) | I14: =IFERROR(__xludf.DUMMYFUNCTION("IF(ISBLANK(D14),"""",IFERROR(XIRR({FILTER('Entradas y salidas'!J:J, 'Entradas y salidas'!D:D=D14, NOT(ISBLANK('Entradas y salidas'!J:J))); INDEX(FILTER('Cortes x inversión'!F:F, 'Cortes x inversión'!D:D=D14),1)}, {FILTER('Entradas y salidas'!F:F, 'Entrada"&"s y salidas'!D:D=D14, NOT(ISBLANK('Entradas y salidas'!J:J))); INDEX(FILTER('Cortes x inversión'!J:J, 'Cortes x inversión'!D:D=D14),1)}), """"))"),"") | K14: =IF(E14="USD", SUMIF('Entradas y salidas'!D:D, D14, 'Entradas y salidas'!I:I), ) | L14: =IFERROR(__xludf.DUMMYFUNCTION("IF(E14=""USD"", INDEX(FILTER('Cortes x inversión'!G:G, 'Cortes x inversión'!D:D=D14),1), )"),"") | M14: =IF(OR(K14="", L14=""),"", L14 - ABS(K14)) | N14: =IFERROR(__xludf.DUMMYFUNCTION("IF(ISBLANK(D14),"""",IFERROR(XIRR({FILTER('Entradas y salidas'!I:I, 'Entradas y salidas'!D:D=D14, NOT(ISBLANK('Entradas y salidas'!I:I))); INDEX(FILTER('Cortes x inversión'!G:G, 'Cortes x inversión'!D:D=D14),1)}, {FILTER('Entradas y salidas'!F:F, 'Entrada"&"s y salidas'!D:D=D14, NOT(ISBLANK('Entradas y salidas'!I:I))); INDEX(FILTER('Cortes x inversión'!J:J, 'Cortes x inversión'!D:D=D14),1)}), """"))"),"") | P14: =IFERROR(__xludf.DUMMYFUNCTION("IF(K14="""","""", GOOGLEFINANCE(""CURRENCY:USDCOP"")) "),"") | Q14: =IFERROR(__xludf.DUMMYFUNCTION("IF(L14="""","""", GOOGLEFINANCE(""CURRENCY:USDCOP"")) "),"") | R14: =IF(K14="","", L14*P14) | S14: =IF(OR(Q14="", R14=""),"", R14 - ABS(Q14)) | T14: =IFERROR(__xludf.DUMMYFUNCTION("IF(ISBLANK(D14),"""",IFERROR(XIRR({FILTER('Entradas y salidas'!K:K, 'Entradas y salidas'!D:D=D14, NOT(ISBLANK('Entradas y salidas'!K:K))); INDEX(FILTER('Cortes x inversión'!I:I, 'Cortes x inversión'!D:D=D14),1)}, {FILTER('Entradas y salidas'!F:F, 'Entrada"&"s y salidas'!D:D=D14, NOT(ISBLANK('Entradas y salidas'!K:K))); INDEX(FILTER('Cortes x inversión'!J:J, 'Cortes x inversión'!D:D=D14),1)}), """"))"),"")
F15: =IF(E15="COP", SUMIF('Entradas y salidas'!D:D, D15, 'Entradas y salidas'!J:J), ) | G15: =IFERROR(__xludf.DUMMYFUNCTION("IF(E15=""COP"", INDEX(FILTER('Cortes x inversión'!F:F, 'Cortes x inversión'!D:D=D15),1), )"),"") | H15: =IF(OR(F15="", G15=""),"", G15 - ABS(F15)) | I15: =IFERROR(__xludf.DUMMYFUNCTION("IF(ISBLANK(D15),"""",IFERROR(XIRR({FILTER('Entradas y salidas'!J:J, 'Entradas y salidas'!D:D=D15, NOT(ISBLANK('Entradas y salidas'!J:J))); INDEX(FILTER('Cortes x inversión'!F:F, 'Cortes x inversión'!D:D=D15),1)}, {FILTER('Entradas y salidas'!F:F, 'Entrada"&"s y salidas'!D:D=D15, NOT(ISBLANK('Entradas y salidas'!J:J))); INDEX(FILTER('Cortes x inversión'!J:J, 'Cortes x inversión'!D:D=D15),1)}), """"))"),"") | K15: =IF(E15="USD", SUMIF('Entradas y salidas'!D:D, D15, 'Entradas y salidas'!I:I), ) | L15: =IFERROR(__xludf.DUMMYFUNCTION("IF(E15=""USD"", INDEX(FILTER('Cortes x inversión'!G:G, 'Cortes x inversión'!D:D=D15),1), )"),"") | M15: =IF(OR(K15="", L15=""),"", L15 - ABS(K15)) | N15: =IFERROR(__xludf.DUMMYFUNCTION("IF(ISBLANK(D15),"""",IFERROR(XIRR({FILTER('Entradas y salidas'!I:I, 'Entradas y salidas'!D:D=D15, NOT(ISBLANK('Entradas y salidas'!I:I))); INDEX(FILTER('Cortes x inversión'!G:G, 'Cortes x inversión'!D:D=D15),1)}, {FILTER('Entradas y salidas'!F:F, 'Entrada"&"s y salidas'!D:D=D15, NOT(ISBLANK('Entradas y salidas'!I:I))); INDEX(FILTER('Cortes x inversión'!J:J, 'Cortes x inversión'!D:D=D15),1)}), """"))"),"") | P15: =IFERROR(__xludf.DUMMYFUNCTION("IF(K15="""","""", GOOGLEFINANCE(""CURRENCY:USDCOP"")) "),"") | Q15: =IFERROR(__xludf.DUMMYFUNCTION("IF(L15="""","""", GOOGLEFINANCE(""CURRENCY:USDCOP"")) "),"") | R15: =IF(K15="","", L15*P15) | S15: =IF(OR(Q15="", R15=""),"", R15 - ABS(Q15)) | T15: =IFERROR(__xludf.DUMMYFUNCTION("IF(ISBLANK(D15),"""",IFERROR(XIRR({FILTER('Entradas y salidas'!K:K, 'Entradas y salidas'!D:D=D15, NOT(ISBLANK('Entradas y salidas'!K:K))); INDEX(FILTER('Cortes x inversión'!I:I, 'Cortes x inversión'!D:D=D15),1)}, {FILTER('Entradas y salidas'!F:F, 'Entrada"&"s y salidas'!D:D=D15, NOT(ISBLANK('Entradas y salidas'!K:K))); INDEX(FILTER('Cortes x inversión'!J:J, 'Cortes x inversión'!D:D=D15),1)}), """"))"),"")
F16: =IF(E16="COP", SUMIF('Entradas y salidas'!D:D, D16, 'Entradas y salidas'!J:J), ) | G16: =IFERROR(__xludf.DUMMYFUNCTION("IF(E16=""COP"", INDEX(FILTER('Cortes x inversión'!F:F, 'Cortes x inversión'!D:D=D16),1), )"),"") | H16: =IF(OR(F16="", G16=""),"", G16 - ABS(F16)) | I16: =IFERROR(__xludf.DUMMYFUNCTION("IF(ISBLANK(D16),"""",IFERROR(XIRR({FILTER('Entradas y salidas'!J:J, 'Entradas y salidas'!D:D=D16, NOT(ISBLANK('Entradas y salidas'!J:J))); INDEX(FILTER('Cortes x inversión'!F:F, 'Cortes x inversión'!D:D=D16),1)}, {FILTER('Entradas y salidas'!F:F, 'Entrada"&"s y salidas'!D:D=D16, NOT(ISBLANK('Entradas y salidas'!J:J))); INDEX(FILTER('Cortes x inversión'!J:J, 'Cortes x inversión'!D:D=D16),1)}), """"))"),"") | K16: =IF(E16="USD", SUMIF('Entradas y salidas'!D:D, D16, 'Entradas y salidas'!I:I), ) | L16: =IFERROR(__xludf.DUMMYFUNCTION("IF(E16=""USD"", INDEX(FILTER('Cortes x inversión'!G:G, 'Cortes x inversión'!D:D=D16),1), )"),"") | M16: =IF(OR(K16="", L16=""),"", L16 - ABS(K16)) | N16: =IFERROR(__xludf.DUMMYFUNCTION("IF(ISBLANK(D16),"""",IFERROR(XIRR({FILTER('Entradas y salidas'!I:I, 'Entradas y salidas'!D:D=D16, NOT(ISBLANK('Entradas y salidas'!I:I))); INDEX(FILTER('Cortes x inversión'!G:G, 'Cortes x inversión'!D:D=D16),1)}, {FILTER('Entradas y salidas'!F:F, 'Entrada"&"s y salidas'!D:D=D16, NOT(ISBLANK('Entradas y salidas'!I:I))); INDEX(FILTER('Cortes x inversión'!J:J, 'Cortes x inversión'!D:D=D16),1)}), """"))"),"") | P16: =IFERROR(__xludf.DUMMYFUNCTION("IF(K16="""","""", GOOGLEFINANCE(""CURRENCY:USDCOP"")) "),"") | Q16: =IFERROR(__xludf.DUMMYFUNCTION("IF(L16="""","""", GOOGLEFINANCE(""CURRENCY:USDCOP"")) "),"") | R16: =IF(K16="","", L16*P16) | S16: =IF(OR(Q16="", R16=""),"", R16 - ABS(Q16)) | T16: =IFERROR(__xludf.DUMMYFUNCTION("IF(ISBLANK(D16),"""",IFERROR(XIRR({FILTER('Entradas y salidas'!K:K, 'Entradas y salidas'!D:D=D16, NOT(ISBLANK('Entradas y salidas'!K:K))); INDEX(FILTER('Cortes x inversión'!I:I, 'Cortes x inversión'!D:D=D16),1)}, {FILTER('Entradas y salidas'!F:F, 'Entrada"&"s y salidas'!D:D=D16, NOT(ISBLANK('Entradas y salidas'!K:K))); INDEX(FILTER('Cortes x inversión'!J:J, 'Cortes x inversión'!D:D=D16),1)}), """"))"),"")
F17: =IF(E17="COP", SUMIF('Entradas y salidas'!D:D, D17, 'Entradas y salidas'!J:J), ) | G17: =IFERROR(__xludf.DUMMYFUNCTION("IF(E17=""COP"", INDEX(FILTER('Cortes x inversión'!F:F, 'Cortes x inversión'!D:D=D17),1), )"),"") | H17: =IF(OR(F17="", G17=""),"", G17 - ABS(F17)) | I17: =IFERROR(__xludf.DUMMYFUNCTION("IF(ISBLANK(D17),"""",IFERROR(XIRR({FILTER('Entradas y salidas'!J:J, 'Entradas y salidas'!D:D=D17, NOT(ISBLANK('Entradas y salidas'!J:J))); INDEX(FILTER('Cortes x inversión'!F:F, 'Cortes x inversión'!D:D=D17),1)}, {FILTER('Entradas y salidas'!F:F, 'Entrada"&"s y salidas'!D:D=D17, NOT(ISBLANK('Entradas y salidas'!J:J))); INDEX(FILTER('Cortes x inversión'!J:J, 'Cortes x inversión'!D:D=D17),1)}), """"))"),"") | K17: =IF(E17="USD", SUMIF('Entradas y salidas'!D:D, D17, 'Entradas y salidas'!I:I), ) | L17: =IFERROR(__xludf.DUMMYFUNCTION("IF(E17=""USD"", INDEX(FILTER('Cortes x inversión'!G:G, 'Cortes x inversión'!D:D=D17),1), )"),"") | M17: =IF(OR(K17="", L17=""),"", L17 - ABS(K17)) | N17: =IFERROR(__xludf.DUMMYFUNCTION("IF(ISBLANK(D17),"""",IFERROR(XIRR({FILTER('Entradas y salidas'!I:I, 'Entradas y salidas'!D:D=D17, NOT(ISBLANK('Entradas y salidas'!I:I))); INDEX(FILTER('Cortes x inversión'!G:G, 'Cortes x inversión'!D:D=D17),1)}, {FILTER('Entradas y salidas'!F:F, 'Entrada"&"s y salidas'!D:D=D17, NOT(ISBLANK('Entradas y salidas'!I:I))); INDEX(FILTER('Cortes x inversión'!J:J, 'Cortes x inversión'!D:D=D17),1)}), """"))"),"") | P17: =IFERROR(__xludf.DUMMYFUNCTION("IF(K17="""","""", GOOGLEFINANCE(""CURRENCY:USDCOP"")) "),"") | Q17: =IFERROR(__xludf.DUMMYFUNCTION("IF(L17="""","""", GOOGLEFINANCE(""CURRENCY:USDCOP"")) "),"") | R17: =IF(K17="","", L17*P17) | S17: =IF(OR(Q17="", R17=""),"", R17 - ABS(Q17)) | T17: =IFERROR(__xludf.DUMMYFUNCTION("IF(ISBLANK(D17),"""",IFERROR(XIRR({FILTER('Entradas y salidas'!K:K, 'Entradas y salidas'!D:D=D17, NOT(ISBLANK('Entradas y salidas'!K:K))); INDEX(FILTER('Cortes x inversión'!I:I, 'Cortes x inversión'!D:D=D17),1)}, {FILTER('Entradas y salidas'!F:F, 'Entrada"&"s y salidas'!D:D=D17, NOT(ISBLANK('Entradas y salidas'!K:K))); INDEX(FILTER('Cortes x inversión'!J:J, 'Cortes x inversión'!D:D=D17),1)}), """"))"),"")
F18: =IF(E18="COP", SUMIF('Entradas y salidas'!D:D, D18, 'Entradas y salidas'!J:J), ) | G18: =IFERROR(__xludf.DUMMYFUNCTION("IF(E18=""COP"", INDEX(FILTER('Cortes x inversión'!F:F, 'Cortes x inversión'!D:D=D18),1), )"),"") | H18: =IF(OR(F18="", G18=""),"", G18 - ABS(F18)) | I18: =IFERROR(__xludf.DUMMYFUNCTION("IF(ISBLANK(D18),"""",IFERROR(XIRR({FILTER('Entradas y salidas'!J:J, 'Entradas y salidas'!D:D=D18, NOT(ISBLANK('Entradas y salidas'!J:J))); INDEX(FILTER('Cortes x inversión'!F:F, 'Cortes x inversión'!D:D=D18),1)}, {FILTER('Entradas y salidas'!F:F, 'Entrada"&"s y salidas'!D:D=D18, NOT(ISBLANK('Entradas y salidas'!J:J))); INDEX(FILTER('Cortes x inversión'!J:J, 'Cortes x inversión'!D:D=D18),1)}), """"))"),"") | K18: =IF(E18="USD", SUMIF('Entradas y salidas'!D:D, D18, 'Entradas y salidas'!I:I), ) | L18: =IFERROR(__xludf.DUMMYFUNCTION("IF(E18=""USD"", INDEX(FILTER('Cortes x inversión'!G:G, 'Cortes x inversión'!D:D=D18),1), )"),"") | M18: =IF(OR(K18="", L18=""),"", L18 - ABS(K18)) | N18: =IFERROR(__xludf.DUMMYFUNCTION("IF(ISBLANK(D18),"""",IFERROR(XIRR({FILTER('Entradas y salidas'!I:I, 'Entradas y salidas'!D:D=D18, NOT(ISBLANK('Entradas y salidas'!I:I))); INDEX(FILTER('Cortes x inversión'!G:G, 'Cortes x inversión'!D:D=D18),1)}, {FILTER('Entradas y salidas'!F:F, 'Entrada"&"s y salidas'!D:D=D18, NOT(ISBLANK('Entradas y salidas'!I:I))); INDEX(FILTER('Cortes x inversión'!J:J, 'Cortes x inversión'!D:D=D18),1)}), """"))"),"") | P18: =IFERROR(__xludf.DUMMYFUNCTION("IF(K18="""","""", GOOGLEFINANCE(""CURRENCY:USDCOP"")) "),"") | Q18: =IFERROR(__xludf.DUMMYFUNCTION("IF(L18="""","""", GOOGLEFINANCE(""CURRENCY:USDCOP"")) "),"") | R18: =IF(K18="","", L18*P18) | S18: =IF(OR(Q18="", R18=""),"", R18 - ABS(Q18)) | T18: =IFERROR(__xludf.DUMMYFUNCTION("IF(ISBLANK(D18),"""",IFERROR(XIRR({FILTER('Entradas y salidas'!K:K, 'Entradas y salidas'!D:D=D18, NOT(ISBLANK('Entradas y salidas'!K:K))); INDEX(FILTER('Cortes x inversión'!I:I, 'Cortes x inversión'!D:D=D18),1)}, {FILTER('Entradas y salidas'!F:F, 'Entrada"&"s y salidas'!D:D=D18, NOT(ISBLANK('Entradas y salidas'!K:K))); INDEX(FILTER('Cortes x inversión'!J:J, 'Cortes x inversión'!D:D=D18),1)}), """"))"),"")
F19: =IF(E19="COP", SUMIF('Entradas y salidas'!D:D, D19, 'Entradas y salidas'!J:J), ) | G19: =IFERROR(__xludf.DUMMYFUNCTION("IF(E19=""COP"", INDEX(FILTER('Cortes x inversión'!F:F, 'Cortes x inversión'!D:D=D19),1), )"),"") | H19: =IF(OR(F19="", G19=""),"", G19 - ABS(F19)) | I19: =IFERROR(__xludf.DUMMYFUNCTION("IF(ISBLANK(D19),"""",IFERROR(XIRR({FILTER('Entradas y salidas'!J:J, 'Entradas y salidas'!D:D=D19, NOT(ISBLANK('Entradas y salidas'!J:J))); INDEX(FILTER('Cortes x inversión'!F:F, 'Cortes x inversión'!D:D=D19),1)}, {FILTER('Entradas y salidas'!F:F, 'Entrada"&"s y salidas'!D:D=D19, NOT(ISBLANK('Entradas y salidas'!J:J))); INDEX(FILTER('Cortes x inversión'!J:J, 'Cortes x inversión'!D:D=D19),1)}), """"))"),"") | K19: =IF(E19="USD", SUMIF('Entradas y salidas'!D:D, D19, 'Entradas y salidas'!I:I), ) | L19: =IFERROR(__xludf.DUMMYFUNCTION("IF(E19=""USD"", INDEX(FILTER('Cortes x inversión'!G:G, 'Cortes x inversión'!D:D=D19),1), )"),"") | M19: =IF(OR(K19="", L19=""),"", L19 - ABS(K19)) | N19: =IFERROR(__xludf.DUMMYFUNCTION("IF(ISBLANK(D19),"""",IFERROR(XIRR({FILTER('Entradas y salidas'!I:I, 'Entradas y salidas'!D:D=D19, NOT(ISBLANK('Entradas y salidas'!I:I))); INDEX(FILTER('Cortes x inversión'!G:G, 'Cortes x inversión'!D:D=D19),1)}, {FILTER('Entradas y salidas'!F:F, 'Entrada"&"s y salidas'!D:D=D19, NOT(ISBLANK('Entradas y salidas'!I:I))); INDEX(FILTER('Cortes x inversión'!J:J, 'Cortes x inversión'!D:D=D19),1)}), """"))"),"") | P19: =IFERROR(__xludf.DUMMYFUNCTION("IF(K19="""","""", GOOGLEFINANCE(""CURRENCY:USDCOP"")) "),"") | Q19: =IFERROR(__xludf.DUMMYFUNCTION("IF(L19="""","""", GOOGLEFINANCE(""CURRENCY:USDCOP"")) "),"") | R19: =IF(K19="","", L19*P19) | S19: =IF(OR(Q19="", R19=""),"", R19 - ABS(Q19)) | T19: =IFERROR(__xludf.DUMMYFUNCTION("IF(ISBLANK(D19),"""",IFERROR(XIRR({FILTER('Entradas y salidas'!K:K, 'Entradas y salidas'!D:D=D19, NOT(ISBLANK('Entradas y salidas'!K:K))); INDEX(FILTER('Cortes x inversión'!I:I, 'Cortes x inversión'!D:D=D19),1)}, {FILTER('Entradas y salidas'!F:F, 'Entrada"&"s y salidas'!D:D=D19, NOT(ISBLANK('Entradas y salidas'!K:K))); INDEX(FILTER('Cortes x inversión'!J:J, 'Cortes x inversión'!D:D=D19),1)}), """"))"),"")
F20: =IF(E20="COP", SUMIF('Entradas y salidas'!D:D, D20, 'Entradas y salidas'!J:J), ) | G20: =IFERROR(__xludf.DUMMYFUNCTION("IF(E20=""COP"", INDEX(FILTER('Cortes x inversión'!F:F, 'Cortes x inversión'!D:D=D20),1), )"),"") | H20: =IF(OR(F20="", G20=""),"", G20 - ABS(F20)) | I20: =IFERROR(__xludf.DUMMYFUNCTION("IF(ISBLANK(D20),"""",IFERROR(XIRR({FILTER('Entradas y salidas'!J:J, 'Entradas y salidas'!D:D=D20, NOT(ISBLANK('Entradas y salidas'!J:J))); INDEX(FILTER('Cortes x inversión'!F:F, 'Cortes x inversión'!D:D=D20),1)}, {FILTER('Entradas y salidas'!F:F, 'Entrada"&"s y salidas'!D:D=D20, NOT(ISBLANK('Entradas y salidas'!J:J))); INDEX(FILTER('Cortes x inversión'!J:J, 'Cortes x inversión'!D:D=D20),1)}), """"))"),"") | K20: =IF(E20="USD", SUMIF('Entradas y salidas'!D:D, D20, 'Entradas y salidas'!I:I), ) | L20: =IFERROR(__xludf.DUMMYFUNCTION("IF(E20=""USD"", INDEX(FILTER('Cortes x inversión'!G:G, 'Cortes x inversión'!D:D=D20),1), )"),"") | M20: =IF(OR(K20="", L20=""),"", L20 - ABS(K20)) | N20: =IFERROR(__xludf.DUMMYFUNCTION("IF(ISBLANK(D20),"""",IFERROR(XIRR({FILTER('Entradas y salidas'!I:I, 'Entradas y salidas'!D:D=D20, NOT(ISBLANK('Entradas y salidas'!I:I))); INDEX(FILTER('Cortes x inversión'!G:G, 'Cortes x inversión'!D:D=D20),1)}, {FILTER('Entradas y salidas'!F:F, 'Entrada"&"s y salidas'!D:D=D20, NOT(ISBLANK('Entradas y salidas'!I:I))); INDEX(FILTER('Cortes x inversión'!J:J, 'Cortes x inversión'!D:D=D20),1)}), """"))"),"") | P20: =IFERROR(__xludf.DUMMYFUNCTION("IF(K20="""","""", GOOGLEFINANCE(""CURRENCY:USDCOP"")) "),"") | Q20: =IFERROR(__xludf.DUMMYFUNCTION("IF(L20="""","""", GOOGLEFINANCE(""CURRENCY:USDCOP"")) "),"") | R20: =IF(K20="","", L20*P20) | S20: =IF(OR(Q20="", R20=""),"", R20 - ABS(Q20)) | T20: =IFERROR(__xludf.DUMMYFUNCTION("IF(ISBLANK(D20),"""",IFERROR(XIRR({FILTER('Entradas y salidas'!K:K, 'Entradas y salidas'!D:D=D20, NOT(ISBLANK('Entradas y salidas'!K:K))); INDEX(FILTER('Cortes x inversión'!I:I, 'Cortes x inversión'!D:D=D20),1)}, {FILTER('Entradas y salidas'!F:F, 'Entrada"&"s y salidas'!D:D=D20, NOT(ISBLANK('Entradas y salidas'!K:K))); INDEX(FILTER('Cortes x inversión'!J:J, 'Cortes x inversión'!D:D=D20),1)}), """"))"),"")
F21: =IF(E21="COP", SUMIF('Entradas y salidas'!D:D, D21, 'Entradas y salidas'!J:J), ) | G21: =IFERROR(__xludf.DUMMYFUNCTION("IF(E21=""COP"", INDEX(FILTER('Cortes x inversión'!F:F, 'Cortes x inversión'!D:D=D21),1), )"),"") | H21: =IF(OR(F21="", G21=""),"", G21 - ABS(F21)) | I21: =IFERROR(__xludf.DUMMYFUNCTION("IF(ISBLANK(D21),"""",IFERROR(XIRR({FILTER('Entradas y salidas'!J:J, 'Entradas y salidas'!D:D=D21, NOT(ISBLANK('Entradas y salidas'!J:J))); INDEX(FILTER('Cortes x inversión'!F:F, 'Cortes x inversión'!D:D=D21),1)}, {FILTER('Entradas y salidas'!F:F, 'Entrada"&"s y salidas'!D:D=D21, NOT(ISBLANK('Entradas y salidas'!J:J))); INDEX(FILTER('Cortes x inversión'!J:J, 'Cortes x inversión'!D:D=D21),1)}), """"))"),"") | K21: =IF(E21="USD", SUMIF('Entradas y salidas'!D:D, D21, 'Entradas y salidas'!I:I), ) | L21: =IFERROR(__xludf.DUMMYFUNCTION("IF(E21=""USD"", INDEX(FILTER('Cortes x inversión'!G:G, 'Cortes x inversión'!D:D=D21),1), )"),"") | M21: =IF(OR(K21="", L21=""),"", L21 - ABS(K21)) | N21: =IFERROR(__xludf.DUMMYFUNCTION("IF(ISBLANK(D21),"""",IFERROR(XIRR({FILTER('Entradas y salidas'!I:I, 'Entradas y salidas'!D:D=D21, NOT(ISBLANK('Entradas y salidas'!I:I))); INDEX(FILTER('Cortes x inversión'!G:G, 'Cortes x inversión'!D:D=D21),1)}, {FILTER('Entradas y salidas'!F:F, 'Entrada"&"s y salidas'!D:D=D21, NOT(ISBLANK('Entradas y salidas'!I:I))); INDEX(FILTER('Cortes x inversión'!J:J, 'Cortes x inversión'!D:D=D21),1)}), """"))"),"") | P21: =IFERROR(__xludf.DUMMYFUNCTION("IF(K21="""","""", GOOGLEFINANCE(""CURRENCY:USDCOP"")) "),"") | Q21: =IFERROR(__xludf.DUMMYFUNCTION("IF(L21="""","""", GOOGLEFINANCE(""CURRENCY:USDCOP"")) "),"") | R21: =IF(K21="","", L21*P21) | S21: =IF(OR(Q21="", R21=""),"", R21 - ABS(Q21)) | T21: =IFERROR(__xludf.DUMMYFUNCTION("IF(ISBLANK(D21),"""",IFERROR(XIRR({FILTER('Entradas y salidas'!K:K, 'Entradas y salidas'!D:D=D21, NOT(ISBLANK('Entradas y salidas'!K:K))); INDEX(FILTER('Cortes x inversión'!I:I, 'Cortes x inversión'!D:D=D21),1)}, {FILTER('Entradas y salidas'!F:F, 'Entrada"&"s y salidas'!D:D=D21, NOT(ISBLANK('Entradas y salidas'!K:K))); INDEX(FILTER('Cortes x inversión'!J:J, 'Cortes x inversión'!D:D=D21),1)}), """"))"),"")
F22: =IF(E22="COP", SUMIF('Entradas y salidas'!D:D, D22, 'Entradas y salidas'!J:J), ) | G22: =IFERROR(__xludf.DUMMYFUNCTION("IF(E22=""COP"", INDEX(FILTER('Cortes x inversión'!F:F, 'Cortes x inversión'!D:D=D22),1), )"),"") | H22: =IF(OR(F22="", G22=""),"", G22 - ABS(F22)) | I22: =IFERROR(__xludf.DUMMYFUNCTION("IF(ISBLANK(D22),"""",IFERROR(XIRR({FILTER('Entradas y salidas'!J:J, 'Entradas y salidas'!D:D=D22, NOT(ISBLANK('Entradas y salidas'!J:J))); INDEX(FILTER('Cortes x inversión'!F:F, 'Cortes x inversión'!D:D=D22),1)}, {FILTER('Entradas y salidas'!F:F, 'Entrada"&"s y salidas'!D:D=D22, NOT(ISBLANK('Entradas y salidas'!J:J))); INDEX(FILTER('Cortes x inversión'!J:J, 'Cortes x inversión'!D:D=D22),1)}), """"))"),"") | K22: =IF(E22="USD", SUMIF('Entradas y salidas'!D:D, D22, 'Entradas y salidas'!I:I), ) | L22: =IFERROR(__xludf.DUMMYFUNCTION("IF(E22=""USD"", INDEX(FILTER('Cortes x inversión'!G:G, 'Cortes x inversión'!D:D=D22),1), )"),"") | M22: =IF(OR(K22="", L22=""),"", L22 - ABS(K22)) | N22: =IFERROR(__xludf.DUMMYFUNCTION("IF(ISBLANK(D22),"""",IFERROR(XIRR({FILTER('Entradas y salidas'!I:I, 'Entradas y salidas'!D:D=D22, NOT(ISBLANK('Entradas y salidas'!I:I))); INDEX(FILTER('Cortes x inversión'!G:G, 'Cortes x inversión'!D:D=D22),1)}, {FILTER('Entradas y salidas'!F:F, 'Entrada"&"s y salidas'!D:D=D22, NOT(ISBLANK('Entradas y salidas'!I:I))); INDEX(FILTER('Cortes x inversión'!J:J, 'Cortes x inversión'!D:D=D22),1)}), """"))"),"") | P22: =IFERROR(__xludf.DUMMYFUNCTION("IF(K22="""","""", GOOGLEFINANCE(""CURRENCY:USDCOP"")) "),"") | Q22: =IFERROR(__xludf.DUMMYFUNCTION("IF(L22="""","""", GOOGLEFINANCE(""CURRENCY:USDCOP"")) "),"") | R22: =IF(K22="","", L22*P22) | S22: =IF(OR(Q22="", R22=""),"", R22 - ABS(Q22)) | T22: =IFERROR(__xludf.DUMMYFUNCTION("IF(ISBLANK(D22),"""",IFERROR(XIRR({FILTER('Entradas y salidas'!K:K, 'Entradas y salidas'!D:D=D22, NOT(ISBLANK('Entradas y salidas'!K:K))); INDEX(FILTER('Cortes x inversión'!I:I, 'Cortes x inversión'!D:D=D22),1)}, {FILTER('Entradas y salidas'!F:F, 'Entrada"&"s y salidas'!D:D=D22, NOT(ISBLANK('Entradas y salidas'!K:K))); INDEX(FILTER('Cortes x inversión'!J:J, 'Cortes x inversión'!D:D=D22),1)}), """"))"),"")
F23: =IF(E23="COP", SUMIF('Entradas y salidas'!D:D, D23, 'Entradas y salidas'!J:J), ) | G23: =IFERROR(__xludf.DUMMYFUNCTION("IF(E23=""COP"", INDEX(FILTER('Cortes x inversión'!F:F, 'Cortes x inversión'!D:D=D23),1), )"),"") | H23: =IF(OR(F23="", G23=""),"", G23 - ABS(F23)) | I23: =IFERROR(__xludf.DUMMYFUNCTION("IF(ISBLANK(D23),"""",IFERROR(XIRR({FILTER('Entradas y salidas'!J:J, 'Entradas y salidas'!D:D=D23, NOT(ISBLANK('Entradas y salidas'!J:J))); INDEX(FILTER('Cortes x inversión'!F:F, 'Cortes x inversión'!D:D=D23),1)}, {FILTER('Entradas y salidas'!F:F, 'Entrada"&"s y salidas'!D:D=D23, NOT(ISBLANK('Entradas y salidas'!J:J))); INDEX(FILTER('Cortes x inversión'!J:J, 'Cortes x inversión'!D:D=D23),1)}), """"))"),"") | K23: =IF(E23="USD", SUMIF('Entradas y salidas'!D:D, D23, 'Entradas y salidas'!I:I), ) | L23: =IFERROR(__xludf.DUMMYFUNCTION("IF(E23=""USD"", INDEX(FILTER('Cortes x inversión'!G:G, 'Cortes x inversión'!D:D=D23),1), )"),"") | M23: =IF(OR(K23="", L23=""),"", L23 - ABS(K23)) | N23: =IFERROR(__xludf.DUMMYFUNCTION("IF(ISBLANK(D23),"""",IFERROR(XIRR({FILTER('Entradas y salidas'!I:I, 'Entradas y salidas'!D:D=D23, NOT(ISBLANK('Entradas y salidas'!I:I))); INDEX(FILTER('Cortes x inversión'!G:G, 'Cortes x inversión'!D:D=D23),1)}, {FILTER('Entradas y salidas'!F:F, 'Entrada"&"s y salidas'!D:D=D23, NOT(ISBLANK('Entradas y salidas'!I:I))); INDEX(FILTER('Cortes x inversión'!J:J, 'Cortes x inversión'!D:D=D23),1)}), """"))"),"") | P23: =IFERROR(__xludf.DUMMYFUNCTION("IF(K23="""","""", GOOGLEFINANCE(""CURRENCY:USDCOP"")) "),"") | Q23: =IFERROR(__xludf.DUMMYFUNCTION("IF(L23="""","""", GOOGLEFINANCE(""CURRENCY:USDCOP"")) "),"") | R23: =IF(K23="","", L23*P23) | S23: =IF(OR(Q23="", R23=""),"", R23 - ABS(Q23)) | T23: =IFERROR(__xludf.DUMMYFUNCTION("IF(ISBLANK(D23),"""",IFERROR(XIRR({FILTER('Entradas y salidas'!K:K, 'Entradas y salidas'!D:D=D23, NOT(ISBLANK('Entradas y salidas'!K:K))); INDEX(FILTER('Cortes x inversión'!I:I, 'Cortes x inversión'!D:D=D23),1)}, {FILTER('Entradas y salidas'!F:F, 'Entrada"&"s y salidas'!D:D=D23, NOT(ISBLANK('Entradas y salidas'!K:K))); INDEX(FILTER('Cortes x inversión'!J:J, 'Cortes x inversión'!D:D=D23),1)}), """"))"),"")
F24: =IF(E24="COP", SUMIF('Entradas y salidas'!D:D, D24, 'Entradas y salidas'!J:J), ) | G24: =IFERROR(__xludf.DUMMYFUNCTION("IF(E24=""COP"", INDEX(FILTER('Cortes x inversión'!F:F, 'Cortes x inversión'!D:D=D24),1), )"),"") | H24: =IF(OR(F24="", G24=""),"", G24 - ABS(F24)) | I24: =IFERROR(__xludf.DUMMYFUNCTION("IF(ISBLANK(D24),"""",IFERROR(XIRR({FILTER('Entradas y salidas'!J:J, 'Entradas y salidas'!D:D=D24, NOT(ISBLANK('Entradas y salidas'!J:J))); INDEX(FILTER('Cortes x inversión'!F:F, 'Cortes x inversión'!D:D=D24),1)}, {FILTER('Entradas y salidas'!F:F, 'Entrada"&"s y salidas'!D:D=D24, NOT(ISBLANK('Entradas y salidas'!J:J))); INDEX(FILTER('Cortes x inversión'!J:J, 'Cortes x inversión'!D:D=D24),1)}), """"))"),"") | K24: =IF(E24="USD", SUMIF('Entradas y salidas'!D:D, D24, 'Entradas y salidas'!I:I), ) | L24: =IFERROR(__xludf.DUMMYFUNCTION("IF(E24=""USD"", INDEX(FILTER('Cortes x inversión'!G:G, 'Cortes x inversión'!D:D=D24),1), )"),"") | M24: =IF(OR(K24="", L24=""),"", L24 - ABS(K24)) | N24: =IFERROR(__xludf.DUMMYFUNCTION("IF(ISBLANK(D24),"""",IFERROR(XIRR({FILTER('Entradas y salidas'!I:I, 'Entradas y salidas'!D:D=D24, NOT(ISBLANK('Entradas y salidas'!I:I))); INDEX(FILTER('Cortes x inversión'!G:G, 'Cortes x inversión'!D:D=D24),1)}, {FILTER('Entradas y salidas'!F:F, 'Entrada"&"s y salidas'!D:D=D24, NOT(ISBLANK('Entradas y salidas'!I:I))); INDEX(FILTER('Cortes x inversión'!J:J, 'Cortes x inversión'!D:D=D24),1)}), """"))"),"") | P24: =IFERROR(__xludf.DUMMYFUNCTION("IF(K24="""","""", GOOGLEFINANCE(""CURRENCY:USDCOP"")) "),"") | Q24: =IFERROR(__xludf.DUMMYFUNCTION("IF(L24="""","""", GOOGLEFINANCE(""CURRENCY:USDCOP"")) "),"") | R24: =IF(K24="","", L24*P24) | S24: =IF(OR(Q24="", R24=""),"", R24 - ABS(Q24)) | T24: =IFERROR(__xludf.DUMMYFUNCTION("IF(ISBLANK(D24),"""",IFERROR(XIRR({FILTER('Entradas y salidas'!K:K, 'Entradas y salidas'!D:D=D24, NOT(ISBLANK('Entradas y salidas'!K:K))); INDEX(FILTER('Cortes x inversión'!I:I, 'Cortes x inversión'!D:D=D24),1)}, {FILTER('Entradas y salidas'!F:F, 'Entrada"&"s y salidas'!D:D=D24, NOT(ISBLANK('Entradas y salidas'!K:K))); INDEX(FILTER('Cortes x inversión'!J:J, 'Cortes x inversión'!D:D=D24),1)}), """"))"),"")
F25: =IF(E25="COP", SUMIF('Entradas y salidas'!D:D, D25, 'Entradas y salidas'!J:J), ) | G25: =IFERROR(__xludf.DUMMYFUNCTION("IF(E25=""COP"", INDEX(FILTER('Cortes x inversión'!F:F, 'Cortes x inversión'!D:D=D25),1), )"),"") | H25: =IF(OR(F25="", G25=""),"", G25 - ABS(F25)) | I25: =IFERROR(__xludf.DUMMYFUNCTION("IF(ISBLANK(D25),"""",IFERROR(XIRR({FILTER('Entradas y salidas'!J:J, 'Entradas y salidas'!D:D=D25, NOT(ISBLANK('Entradas y salidas'!J:J))); INDEX(FILTER('Cortes x inversión'!F:F, 'Cortes x inversión'!D:D=D25),1)}, {FILTER('Entradas y salidas'!F:F, 'Entrada"&"s y salidas'!D:D=D25, NOT(ISBLANK('Entradas y salidas'!J:J))); INDEX(FILTER('Cortes x inversión'!J:J, 'Cortes x inversión'!D:D=D25),1)}), """"))"),"") | K25: =IF(E25="USD", SUMIF('Entradas y salidas'!D:D, D25, 'Entradas y salidas'!I:I), ) | L25: =IFERROR(__xludf.DUMMYFUNCTION("IF(E25=""USD"", INDEX(FILTER('Cortes x inversión'!G:G, 'Cortes x inversión'!D:D=D25),1), )"),"") | M25: =IF(OR(K25="", L25=""),"", L25 - ABS(K25)) | N25: =IFERROR(__xludf.DUMMYFUNCTION("IF(ISBLANK(D25),"""",IFERROR(XIRR({FILTER('Entradas y salidas'!I:I, 'Entradas y salidas'!D:D=D25, NOT(ISBLANK('Entradas y salidas'!I:I))); INDEX(FILTER('Cortes x inversión'!G:G, 'Cortes x inversión'!D:D=D25),1)}, {FILTER('Entradas y salidas'!F:F, 'Entrada"&"s y salidas'!D:D=D25, NOT(ISBLANK('Entradas y salidas'!I:I))); INDEX(FILTER('Cortes x inversión'!J:J, 'Cortes x inversión'!D:D=D25),1)}), """"))"),"") | P25: =IFERROR(__xludf.DUMMYFUNCTION("IF(K25="""","""", GOOGLEFINANCE(""CURRENCY:USDCOP"")) "),"") | Q25: =IFERROR(__xludf.DUMMYFUNCTION("IF(L25="""","""", GOOGLEFINANCE(""CURRENCY:USDCOP"")) "),"") | R25: =IF(K25="","", L25*P25) | S25: =IF(OR(Q25="", R25=""),"", R25 - ABS(Q25)) | T25: =IFERROR(__xludf.DUMMYFUNCTION("IF(ISBLANK(D25),"""",IFERROR(XIRR({FILTER('Entradas y salidas'!K:K, 'Entradas y salidas'!D:D=D25, NOT(ISBLANK('Entradas y salidas'!K:K))); INDEX(FILTER('Cortes x inversión'!I:I, 'Cortes x inversión'!D:D=D25),1)}, {FILTER('Entradas y salidas'!F:F, 'Entrada"&"s y salidas'!D:D=D25, NOT(ISBLANK('Entradas y salidas'!K:K))); INDEX(FILTER('Cortes x inversión'!J:J, 'Cortes x inversión'!D:D=D25),1)}), """"))"),"")
F26: =IF(E26="COP", SUMIF('Entradas y salidas'!D:D, D26, 'Entradas y salidas'!J:J), ) | G26: =IFERROR(__xludf.DUMMYFUNCTION("IF(E26=""COP"", INDEX(FILTER('Cortes x inversión'!F:F, 'Cortes x inversión'!D:D=D26),1), )"),"") | H26: =IF(OR(F26="", G26=""),"", G26 - ABS(F26)) | I26: =IFERROR(__xludf.DUMMYFUNCTION("IF(ISBLANK(D26),"""",IFERROR(XIRR({FILTER('Entradas y salidas'!J:J, 'Entradas y salidas'!D:D=D26, NOT(ISBLANK('Entradas y salidas'!J:J))); INDEX(FILTER('Cortes x inversión'!F:F, 'Cortes x inversión'!D:D=D26),1)}, {FILTER('Entradas y salidas'!F:F, 'Entrada"&"s y salidas'!D:D=D26, NOT(ISBLANK('Entradas y salidas'!J:J))); INDEX(FILTER('Cortes x inversión'!J:J, 'Cortes x inversión'!D:D=D26),1)}), """"))"),"") | K26: =IF(E26="USD", SUMIF('Entradas y salidas'!D:D, D26, 'Entradas y salidas'!I:I), ) | L26: =IFERROR(__xludf.DUMMYFUNCTION("IF(E26=""USD"", INDEX(FILTER('Cortes x inversión'!G:G, 'Cortes x inversión'!D:D=D26),1), )"),"") | M26: =IF(OR(K26="", L26=""),"", L26 - ABS(K26)) | N26: =IFERROR(__xludf.DUMMYFUNCTION("IF(ISBLANK(D26),"""",IFERROR(XIRR({FILTER('Entradas y salidas'!I:I, 'Entradas y salidas'!D:D=D26, NOT(ISBLANK('Entradas y salidas'!I:I))); INDEX(FILTER('Cortes x inversión'!G:G, 'Cortes x inversión'!D:D=D26),1)}, {FILTER('Entradas y salidas'!F:F, 'Entrada"&"s y salidas'!D:D=D26, NOT(ISBLANK('Entradas y salidas'!I:I))); INDEX(FILTER('Cortes x inversión'!J:J, 'Cortes x inversión'!D:D=D26),1)}), """"))"),"") | P26: =IFERROR(__xludf.DUMMYFUNCTION("IF(K26="""","""", GOOGLEFINANCE(""CURRENCY:USDCOP"")) "),"") | Q26: =IFERROR(__xludf.DUMMYFUNCTION("IF(L26="""","""", GOOGLEFINANCE(""CURRENCY:USDCOP"")) "),"") | R26: =IF(K26="","", L26*P26) | S26: =IF(OR(Q26="", R26=""),"", R26 - ABS(Q26)) | T26: =IFERROR(__xludf.DUMMYFUNCTION("IF(ISBLANK(D26),"""",IFERROR(XIRR({FILTER('Entradas y salidas'!K:K, 'Entradas y salidas'!D:D=D26, NOT(ISBLANK('Entradas y salidas'!K:K))); INDEX(FILTER('Cortes x inversión'!I:I, 'Cortes x inversión'!D:D=D26),1)}, {FILTER('Entradas y salidas'!F:F, 'Entrada"&"s y salidas'!D:D=D26, NOT(ISBLANK('Entradas y salidas'!K:K))); INDEX(FILTER('Cortes x inversión'!J:J, 'Cortes x inversión'!D:D=D26),1)}), """"))"),"")
F27: =IF(E27="COP", SUMIF('Entradas y salidas'!D:D, D27, 'Entradas y salidas'!J:J), ) | G27: =IFERROR(__xludf.DUMMYFUNCTION("IF(E27=""COP"", INDEX(FILTER('Cortes x inversión'!F:F, 'Cortes x inversión'!D:D=D27),1), )"),"") | H27: =IF(OR(F27="", G27=""),"", G27 - ABS(F27)) | I27: =IFERROR(__xludf.DUMMYFUNCTION("IF(ISBLANK(D27),"""",IFERROR(XIRR({FILTER('Entradas y salidas'!J:J, 'Entradas y salidas'!D:D=D27, NOT(ISBLANK('Entradas y salidas'!J:J))); INDEX(FILTER('Cortes x inversión'!F:F, 'Cortes x inversión'!D:D=D27),1)}, {FILTER('Entradas y salidas'!F:F, 'Entrada"&"s y salidas'!D:D=D27, NOT(ISBLANK('Entradas y salidas'!J:J))); INDEX(FILTER('Cortes x inversión'!J:J, 'Cortes x inversión'!D:D=D27),1)}), """"))"),"") | K27: =IF(E27="USD", SUMIF('Entradas y salidas'!D:D, D27, 'Entradas y salidas'!I:I), ) | L27: =IFERROR(__xludf.DUMMYFUNCTION("IF(E27=""USD"", INDEX(FILTER('Cortes x inversión'!G:G, 'Cortes x inversión'!D:D=D27),1), )"),"") | M27: =IF(OR(K27="", L27=""),"", L27 - ABS(K27)) | N27: =IFERROR(__xludf.DUMMYFUNCTION("IF(ISBLANK(D27),"""",IFERROR(XIRR({FILTER('Entradas y salidas'!I:I, 'Entradas y salidas'!D:D=D27, NOT(ISBLANK('Entradas y salidas'!I:I))); INDEX(FILTER('Cortes x inversión'!G:G, 'Cortes x inversión'!D:D=D27),1)}, {FILTER('Entradas y salidas'!F:F, 'Entrada"&"s y salidas'!D:D=D27, NOT(ISBLANK('Entradas y salidas'!I:I))); INDEX(FILTER('Cortes x inversión'!J:J, 'Cortes x inversión'!D:D=D27),1)}), """"))"),"") | P27: =IFERROR(__xludf.DUMMYFUNCTION("IF(K27="""","""", GOOGLEFINANCE(""CURRENCY:USDCOP"")) "),"") | Q27: =IFERROR(__xludf.DUMMYFUNCTION("IF(L27="""","""", GOOGLEFINANCE(""CURRENCY:USDCOP"")) "),"") | R27: =IF(K27="","", L27*P27) | S27: =IF(OR(Q27="", R27=""),"", R27 - ABS(Q27)) | T27: =IFERROR(__xludf.DUMMYFUNCTION("IF(ISBLANK(D27),"""",IFERROR(XIRR({FILTER('Entradas y salidas'!K:K, 'Entradas y salidas'!D:D=D27, NOT(ISBLANK('Entradas y salidas'!K:K))); INDEX(FILTER('Cortes x inversión'!I:I, 'Cortes x inversión'!D:D=D27),1)}, {FILTER('Entradas y salidas'!F:F, 'Entrada"&"s y salidas'!D:D=D27, NOT(ISBLANK('Entradas y salidas'!K:K))); INDEX(FILTER('Cortes x inversión'!J:J, 'Cortes x inversión'!D:D=D27),1)}), """"))"),"")
F28: =IF(E28="COP", SUMIF('Entradas y salidas'!D:D, D28, 'Entradas y salidas'!J:J), ) | G28: =IFERROR(__xludf.DUMMYFUNCTION("IF(E28=""COP"", INDEX(FILTER('Cortes x inversión'!F:F, 'Cortes x inversión'!D:D=D28),1), )"),"") | H28: =IF(OR(F28="", G28=""),"", G28 - ABS(F28)) | I28: =IFERROR(__xludf.DUMMYFUNCTION("IF(ISBLANK(D28),"""",IFERROR(XIRR({FILTER('Entradas y salidas'!J:J, 'Entradas y salidas'!D:D=D28, NOT(ISBLANK('Entradas y salidas'!J:J))); INDEX(FILTER('Cortes x inversión'!F:F, 'Cortes x inversión'!D:D=D28),1)}, {FILTER('Entradas y salidas'!F:F, 'Entrada"&"s y salidas'!D:D=D28, NOT(ISBLANK('Entradas y salidas'!J:J))); INDEX(FILTER('Cortes x inversión'!J:J, 'Cortes x inversión'!D:D=D28),1)}), """"))"),"") | K28: =IF(E28="USD", SUMIF('Entradas y salidas'!D:D, D28, 'Entradas y salidas'!I:I), ) | L28: =IFERROR(__xludf.DUMMYFUNCTION("IF(E28=""USD"", INDEX(FILTER('Cortes x inversión'!G:G, 'Cortes x inversión'!D:D=D28),1), )"),"") | M28: =IF(OR(K28="", L28=""),"", L28 - ABS(K28)) | N28: =IFERROR(__xludf.DUMMYFUNCTION("IF(ISBLANK(D28),"""",IFERROR(XIRR({FILTER('Entradas y salidas'!I:I, 'Entradas y salidas'!D:D=D28, NOT(ISBLANK('Entradas y salidas'!I:I))); INDEX(FILTER('Cortes x inversión'!G:G, 'Cortes x inversión'!D:D=D28),1)}, {FILTER('Entradas y salidas'!F:F, 'Entrada"&"s y salidas'!D:D=D28, NOT(ISBLANK('Entradas y salidas'!I:I))); INDEX(FILTER('Cortes x inversión'!J:J, 'Cortes x inversión'!D:D=D28),1)}), """"))"),"") | P28: =IFERROR(__xludf.DUMMYFUNCTION("IF(K28="""","""", GOOGLEFINANCE(""CURRENCY:USDCOP"")) "),"") | Q28: =IFERROR(__xludf.DUMMYFUNCTION("IF(L28="""","""", GOOGLEFINANCE(""CURRENCY:USDCOP"")) "),"") | R28: =IF(K28="","", L28*P28) | S28: =IF(OR(Q28="", R28=""),"", R28 - ABS(Q28)) | T28: =IFERROR(__xludf.DUMMYFUNCTION("IF(ISBLANK(D28),"""",IFERROR(XIRR({FILTER('Entradas y salidas'!K:K, 'Entradas y salidas'!D:D=D28, NOT(ISBLANK('Entradas y salidas'!K:K))); INDEX(FILTER('Cortes x inversión'!I:I, 'Cortes x inversión'!D:D=D28),1)}, {FILTER('Entradas y salidas'!F:F, 'Entrada"&"s y salidas'!D:D=D28, NOT(ISBLANK('Entradas y salidas'!K:K))); INDEX(FILTER('Cortes x inversión'!J:J, 'Cortes x inversión'!D:D=D28),1)}), """"))"),"")
F29: =IF(E29="COP", SUMIF('Entradas y salidas'!D:D, D29, 'Entradas y salidas'!J:J), ) | G29: =IFERROR(__xludf.DUMMYFUNCTION("IF(E29=""COP"", INDEX(FILTER('Cortes x inversión'!F:F, 'Cortes x inversión'!D:D=D29),1), )"),"") | H29: =IF(OR(F29="", G29=""),"", G29 - ABS(F29)) | I29: =IFERROR(__xludf.DUMMYFUNCTION("IF(ISBLANK(D29),"""",IFERROR(XIRR({FILTER('Entradas y salidas'!J:J, 'Entradas y salidas'!D:D=D29, NOT(ISBLANK('Entradas y salidas'!J:J))); INDEX(FILTER('Cortes x inversión'!F:F, 'Cortes x inversión'!D:D=D29),1)}, {FILTER('Entradas y salidas'!F:F, 'Entrada"&"s y salidas'!D:D=D29, NOT(ISBLANK('Entradas y salidas'!J:J))); INDEX(FILTER('Cortes x inversión'!J:J, 'Cortes x inversión'!D:D=D29),1)}), """"))"),"") | K29: =IF(E29="USD", SUMIF('Entradas y salidas'!D:D, D29, 'Entradas y salidas'!I:I), ) | L29: =IFERROR(__xludf.DUMMYFUNCTION("IF(E29=""USD"", INDEX(FILTER('Cortes x inversión'!G:G, 'Cortes x inversión'!D:D=D29),1), )"),"") | M29: =IF(OR(K29="", L29=""),"", L29 - ABS(K29)) | N29: =IFERROR(__xludf.DUMMYFUNCTION("IF(ISBLANK(D29),"""",IFERROR(XIRR({FILTER('Entradas y salidas'!I:I, 'Entradas y salidas'!D:D=D29, NOT(ISBLANK('Entradas y salidas'!I:I))); INDEX(FILTER('Cortes x inversión'!G:G, 'Cortes x inversión'!D:D=D29),1)}, {FILTER('Entradas y salidas'!F:F, 'Entrada"&"s y salidas'!D:D=D29, NOT(ISBLANK('Entradas y salidas'!I:I))); INDEX(FILTER('Cortes x inversión'!J:J, 'Cortes x inversión'!D:D=D29),1)}), """"))"),"") | P29: =IFERROR(__xludf.DUMMYFUNCTION("IF(K29="""","""", GOOGLEFINANCE(""CURRENCY:USDCOP"")) "),"") | Q29: =IFERROR(__xludf.DUMMYFUNCTION("IF(L29="""","""", GOOGLEFINANCE(""CURRENCY:USDCOP"")) "),"") | R29: =IF(K29="","", L29*P29) | S29: =IF(OR(Q29="", R29=""),"", R29 - ABS(Q29)) | T29: =IFERROR(__xludf.DUMMYFUNCTION("IF(ISBLANK(D29),"""",IFERROR(XIRR({FILTER('Entradas y salidas'!K:K, 'Entradas y salidas'!D:D=D29, NOT(ISBLANK('Entradas y salidas'!K:K))); INDEX(FILTER('Cortes x inversión'!I:I, 'Cortes x inversión'!D:D=D29),1)}, {FILTER('Entradas y salidas'!F:F, 'Entrada"&"s y salidas'!D:D=D29, NOT(ISBLANK('Entradas y salidas'!K:K))); INDEX(FILTER('Cortes x inversión'!J:J, 'Cortes x inversión'!D:D=D29),1)}), """"))"),"")
